<?xml version="1.0" ?>
<!-- =================================================================================== -->
<!-- |    This document was autogenerated by xacro from /home/kript0n/catkin_ws/src/fish/urdf/fish.urdf.xacro | -->
<!-- |    EDITING THIS FILE BY HAND IS NOT RECOMMENDED                                 | -->
<!-- =================================================================================== -->
<robot name="fish" xmlns:xacro="http://www.ros.org/wiki/xacro">
  <!-- Creating reference frame  -->
  <link name="world"/>
  <!--<link name="base_link" />-->
  <!-- FISH -->
  <link name="body_link">
    <visual>
      <geometry>
        <mesh filename="file:///home/kript0n/catkin_ws/src/fish/meshes/Tail_zapolnennie.STL" scale="0.001 0.001 0.001"/>
      </geometry>
      <material name="Green">
        <color rgba="0.2 1.0 0.2 1.0"/>
      </material>
      <origin rpy="0.0 0.0 0.0" xyz="0.0 0.0 0.0"/>
    </visual>
    <collision>
      <geometry>
        <mesh filename="file:///home/kript0n/catkin_ws/src/fish/meshes/Tail_zapolnennie.STL" scale="0.001 0.001 0.001"/>
      </geometry>
    </collision>
    <inertial>
      <origin rpy="0.0 0.0 0.0" xyz="0.3447 0.10736 0.063"/>
      <mass value="6.5"/>
      <inertia ixx="0.022636377" ixy="0.001191355" ixz="0.0" iyy="0.142422100" iyz="0.0" izz="0.15464559"/>
    </inertial>
  </link>
  <!-- TAIL -->
  <link name="tail_link">
    <visual>
      <geometry>
        <mesh filename="file:///home/kript0n/catkin_ws/src/fish/meshes/Tail.STL" scale="0.001 0.001 0.001"/>
      </geometry>
      <material name="Green">
        <color rgba="0.2 1.0 0.2 1.0"/>
      </material>
      <!--xyz="0.70705 -0.01004 0.04165"-->
      <origin rpy="0.0 0.0 0.0" xyz="-0.0101009 -0.1244513 -0.02143235"/>
    </visual>
    <collision>
      <geometry>
        <mesh filename="file:///home/kript0n/catkin_ws/src/fish/meshes/Tail.STL" scale="0.001 0.001 0.001"/>
      </geometry>
    </collision>
    <inertial>
      <origin rpy="0.0 0.0 0.0" xyz="0.14137 0.0 0.0"/>
      <mass value="0.687"/>
      <inertia ixx="0.000273771" ixy="0.0" ixz="0.0" iyy="0.00075492555" iyz="0.0" izz="0.00102785965"/>
    </inertial>
  </link>
  <joint name="tail_joint" type="revolute">
    <parent link="body_link"/>
    <child link="tail_link"/>
    <origin rpy="0.0 0.0 0.0" xyz="0.71715009 0.1144113 0.06308235"/>
    <axis xyz="0 1 0"/>
    <limit effort="30" lower="-0.523598775598" upper="0.523598775598" velocity="1.57079632679"/>
  </joint>
  <!-- CONTROL PLUGIN -->
  <joint name="world_joint" type="floating">
    <parent link="world"/>
    <child link="body_link"/>
    <origin rpy="1.57079632679 0.0 0.0" xyz="0.0 0.0 0.0"/>
  </joint>
  <gazebo reference="body_link">
    <material>Gazebo/Green</material>
    <kp>100000.0</kp>
    <kd>100000.0</kd>
    <mu1>10.0</mu1>
    <mu2>10.0</mu2>
  </gazebo>
  <gazebo reference="tail_link">
    <material>Gazebo/Green</material>
    <kp>100000.0</kp>
    <kd>100000.0</kd>
    <mu1>10.0</mu1>
    <mu2>10.0</mu2>
  </gazebo>
  <gazebo>
    <plugin filename="libgazebo_ros_control.so" name="gazebo_ros_control">
      <robotNamespace>/fish</robotNamespace>
    </plugin>
    <plugin filename="libBuoyancyPlugin.so" name="buoyancy">
      <link name="body_link">
        <center_of_volume>0.3447 0.10736 0.0630</center_of_volume>
        <volume>0.005830207</volume>
      </link>
      <link name="tail_link">
        <center_of_volume>0.14137 0.12445 0.02142</center_of_volume>
        <volume>0.000122907</volume>
      </link>
      <fluid_density>1030</fluid_density>
    </plugin>
    <plugin filename="libLiftDragPlugin.so" name="fish_tail">
      <link_name>tail_link</link_name>
      <air_density>1000</air_density>
      <cla>0.2969</cla>
      <cla_stall>-0.1044</cla_stall>
      <cda>0</cda>
      <cda_stall>0.1044</cda_stall>
      <alpha_stall>0.3368</alpha_stall>
      <a0>0</a0>
      <area>0.041820095</area>
      <upward>-0.330514 0.943801 0</upward>
      <forward>0.943801  0.330514 0</forward>
      <cp>0.14137 0.12445 0.02142</cp>
    </plugin>
  </gazebo>
  <!-- FOR ROS CONTROL -->
  <transmission name="tran1">
    <type>transmission_interface/SimpleTransmission</type>
    <joint name="tail_joint">
      <hardwareInterface>EffortJointInterface</hardwareInterface>
    </joint>
    <actuator name="motor1">
      <hardwareInterface>EffortJointInterface</hardwareInterface>
      <mechanicalReduction>1</mechanicalReduction>
    </actuator>
  </transmission>
</robot>
