<?xml version="1.0" ?>
<!-- =================================================================================== -->
<!-- |    This document was autogenerated by xacro from /home/kript0n/catkin_ws/src/fish/urdf/fish.urdf.xacro | -->
<!-- |    EDITING THIS FILE BY HAND IS NOT RECOMMENDED                                 | -->
<!-- =================================================================================== -->
<robot name="fish" xmlns:xacro="http://www.ros.org/wiki/xacro">
  <!-- Creating reference frame  -->
  <link name="world"/>
  <!--<link name="base_link" />-->
  <!-- FISH -->
  <link name="body_link">
    <visual>
      <geometry>
        <mesh filename="file:///home/kript0n/catkin_ws/src/fish/meshes/Torpeda.STL" scale="0.001 0.001 0.001"/>
      </geometry>
      <material name="Green">
        <color rgba="0.2 1.0 0.2 1.0"/>
      </material>
      <origin rpy="0.0 0.0 0.0" xyz="0.0 0.0 0.0"/>
    </visual>
    <collision>
      <geometry>
        <mesh filename="file:///home/kript0n/catkin_ws/src/fish/meshes/Torpeda.STL" scale="0.001 0.001 0.001"/>
      </geometry>
    </collision>
    <inertial>
      <origin rpy="0.0 0.0 0.0" xyz="0.31665 0.10664 0.06385"/>
      <mass value="54.54"/>
      <inertia ixx="0.20628980082" ixy="0.0" ixz="0.0" iyy="0.94202350902" iyz="0.0" izz="1.05359207913"/>
    </inertial>
  </link>
  <!--
  <link name="tail_link">
    <visual>
      <geometry>
        <mesh filename="file://$(find fish)/meshes/Tail.STL" scale="${mesh_scale}"/>
      </geometry>
      <material name="Green">
        <color rgba="0.2 1.0 0.2 1.0"/>
      </material>

      <origin rpy="0.715 0.0 0.0" xyz="0.0 0.0 0.0" />
    </visual>

    <collision>
      <geometry>
        <mesh filename="file://$(find fish)/meshes/Tail.stl" scale="${mesh_scale}" />
      </geometry>
    </collision>

    <inertial>
      <origin rpy="0.0 0.0 0.0" xyz="${body_center_gravity}"/>
      <mass value="${body_mass}"/>
      <inertia ixx="0.0198179" ixy="0.0" ixz="0.0"
        iyy="0.129511" iyz="0.0"  izz="0.14009"/>
    </inertial>
  </link>
    -->
  <!-- CONTROL PLUGIN -->
  <joint name="world_joint" type="floating">
    <parent link="world"/>
    <child link="body_link"/>
    <origin rpy="1.57079632679 0.0 0.0" xyz="0.0 0.0 0.0"/>
  </joint>
  <gazebo reference="body_link">
    <material>Gazebo/Green</material>
    <kp>100000.0</kp>
    <kd>100000.0</kd>
    <mu1>10.0</mu1>
    <mu2>10.0</mu2>
    &gt;
  
  </gazebo>
  <gazebo>
    <plugin filename="libgazebo_ros_control.so" name="gazebo_ros_control">
      <robotNamespace>/</robotNamespace>
    </plugin>
    <plugin filename="libBuoyancyPlugin.so" name="buoyancy">
      <link name="body_link">
        <center_of_volume>0.31665 0.10664 0.06385</center_of_volume>
        <volume>0.05295219</volume>
      </link>
      <fluid_density>1030</fluid_density>
    </plugin>
  </gazebo>
</robot>
