<?xml version="1.0"?>

<robot name="fish" xmlns:xacro="http://www.ros.org/wiki/xacro">
  <xacro:property name="mesh_scale" value="0.001 0.001 0.001" />
  
  <xacro:property name="body_center_gravity" value="0.31665 0.10664 0.06385"/>
  <xacro:property name="body_mass" value="54.54" />
  <xacro:property name="volume" value="0.05295219" />

  <xacro:property name="model_name" value="Torpeda.STL" />

<!-- Creating reference frame  -->
  <link name="world" />
  <!--<link name="base_link" />-->


<!-- FISH -->
  <link name="body_link">
    <visual>
      <geometry>
        <mesh filename="file://$(find fish)/meshes/${model_name}" scale="${mesh_scale}"/>
      </geometry>
      <material name="Green">
        <color rgba="0.2 1.0 0.2 1.0"/>
      </material>

      <origin rpy="0.0 0.0 0.0" xyz="0.0 0.0 0.0" />
    </visual>

    <collision>
      <geometry>
        <mesh filename="file://$(find fish)/meshes/${model_name}" scale="${mesh_scale}" />
      </geometry>
    </collision>

    <inertial>
      <origin rpy="0.0 0.0 0.0" xyz="${body_center_gravity}"/>
      <mass value="${body_mass}"/>
      <inertia ixx="0.20628980082" ixy="0.0" ixz="0.0"
        iyy="0.94202350902" iyz="0.0"  izz="1.05359207913"/>
    </inertial>
  </link>

  <!--
  <link name="tail_link">
    <visual>
      <geometry>
        <mesh filename="file://$(find fish)/meshes/Tail.STL" scale="${mesh_scale}"/>
      </geometry>
      <material name="Green">
        <color rgba="0.2 1.0 0.2 1.0"/>
      </material>

      <origin rpy="0.715 0.0 0.0" xyz="0.0 0.0 0.0" />
    </visual>

    <collision>
      <geometry>
        <mesh filename="file://$(find fish)/meshes/Tail.stl" scale="${mesh_scale}" />
      </geometry>
    </collision>

    <inertial>
      <origin rpy="0.0 0.0 0.0" xyz="${body_center_gravity}"/>
      <mass value="${body_mass}"/>
      <inertia ixx="0.0198179" ixy="0.0" ixz="0.0"
        iyy="0.129511" iyz="0.0"  izz="0.14009"/>
    </inertial>
  </link>
    -->


  <!-- CONTROL PLUGIN -->
	<joint name="world_joint" type="floating">
		<parent link="world"/>
		<child link="body_link"/>
    <origin rpy="${pi/2} 0.0 0.0" xyz="0.0 0.0 0.0" />
  </joint>
  
  <gazebo reference="body_link">
    <material>Gazebo/Green</material>
    <kp>100000.0</kp>
    <kd>100000.0</kd>
    <mu1>10.0</mu1>
    <mu2>10.0</mu2>>
  </gazebo> 
  
  <gazebo>
    <plugin name="gazebo_ros_control" filename="libgazebo_ros_control.so">
      <robotNamespace>/</robotNamespace>
    </plugin>
  
    <plugin name="buoyancy" filename="libBuoyancyPlugin.so">
      <link name="body_link">
        <center_of_volume>0.31665 0.10664 0.06385</center_of_volume>
        <volume>0.05295219</volume>
      </link>

      <fluid_density>1030</fluid_density>
    </plugin>
  </gazebo>


</robot>

