<?xml version="1.0"?>

<robot name="fish" xmlns:xacro="http://www.ros.org/wiki/xacro">
  <xacro:property name="mesh_scale" value="0.001 0.001 0.001" />
  
  <xacro:property name="body_mass" value="${23.343741186}" />
  <xacro:property name="tail_mass" value="${0.6044864}" />

  <xacro:property name="model_name" value="Tail_zapolnennie.STL" />

<!-- Creating reference frame  -->
  <link name="world" />
  <!--<link name="base_link" />-->


<!-- FISH -->
  <link name="body_link">
    <visual>
      <geometry>
        <mesh filename="file://$(find fish)/meshes/${model_name}" scale="${mesh_scale}"/>
      </geometry>
      <material name="Green">
        <color rgba="0.2 1.0 0.2 1.0"/>
      </material>

      <origin rpy="0.0 0.0 0.0" xyz="0.0 0.0 0.0" />
    </visual>

    <collision>
      <geometry>
        <cylinder radius="${0.206 / 2}" length="${0.726 - 0.046}" />
        <!--<box size="${0.726 - 0.016} 0.206 0.106"/> -->
        <!--<mesh filename="file://$(find fish)/meshes/${model_name}" scale="${mesh_scale}" />-->
      </geometry>
      <origin rpy="0.0 ${pi/2} 0.0" xyz="0.363 ${0.103 + 0.010} ${0.053 + 0.011}" />
    </collision>

    <inertial>
      <origin rpy="0.0 0.0 0.0" xyz="0.363 ${0.103 + 0.010} ${0.053 + 0.011}" />
      <mass value="${body_mass}"/>
      <inertia ixx="0.123826875" ixy="0.0" ixz="0.0"
        iyy="0.961425598" iyz="0.0"  izz="0.961425598"/>
    </inertial>
  </link>

  <!-- TAIL -->
  <link name="tail_link">
    <visual>
      <geometry>
        <mesh filename="file://$(find fish)/meshes/Tail.STL" scale="${mesh_scale}"/>
      </geometry>
      <material name="Green">
        <color rgba="0.2 1.0 0.2 1.0"/>
      </material>
    <!--xyz="0.70705 -0.01004 0.04165"-->
      <origin rpy="0.0 0.0 0.0" xyz="-0.0101009 -0.1244513 -0.02143235"/>
    </visual>

    <collision>
      <geometry>
        <cylinder radius="${0.272 / 2.0}" length="${0.0101}" />
        <!--<box size="${0.272 - 0.022} 0.210 0.0101"/> -->
        <!--<mesh filename="file://$(find fish)/meshes/Tail.STL" scale="${mesh_scale}" />-->
      </geometry>
      <origin rpy="0.0 0.0 0.0" xyz="0.14147 0.0 0.0"/>
    </collision>

    <inertial>
      <origin rpy="0.0 0.0 0.0" xyz="0.14147 0.0 0.0"/>
      <mass value="${tail_mass}"/>
      <inertia ixx="0.002800282" ixy="0.0" ixz="0.0"
        iyy="0.005590287" iyz="0.0"  izz="0.005590287"/>
    </inertial>
  </link>

  <joint name="tail_joint" type="revolute">
    <parent link="body_link"/>
    <child link="tail_link"/>
    <origin rpy="0.0 0.0 0.0" xyz="0.71715009 0.1144113 0.06308235"/>
    <axis xyz="0 1 0"/>
    <limit lower="${-pi/6}" upper="${pi/6}" velocity="${pi/2}" effort="100" />
  </joint>


  <!-- CONTROL PLUGIN -->
	<joint name="world_joint" type="floating">
		<parent link="world"/>
		<child link="body_link"/>
    <origin rpy="${pi/2} 0.0 0.0" xyz="0.0 0.0 0.0" />
  </joint>

  
  <gazebo reference="body_link">
    <material>Gazebo/Green</material>
    <kp>100000.0</kp>
    <kd>100000.0</kd>
    <mu1>10.0</mu1>
    <mu2>10.0</mu2>
  </gazebo> 
  
  <gazebo reference="tail_link">
    <material>Gazebo/Green</material>
    <kp>100000.0</kp>
    <kd>100000.0</kd>
    <mu1>10.0</mu1>
    <mu2>10.0</mu2>
  </gazebo> 
  
  <gazebo>
    <plugin name="gazebo_ros_control" filename="libgazebo_ros_control.so">
      <robotNamespace>/fish</robotNamespace>
    </plugin>
  
    <plugin name="buoyancy" filename="libBuoyancyPlugin.so">
      <link name="body_link">
        <!--<center_of_volume></center_of_volume>-->
        <volume>0.022663826</volume>
      </link>

      <link name="tail_link">
        <!--<center_of_volume>0.14137 0.12445 0.02142</center_of_volume>-->
        <volume>0.00058688</volume>
      </link>

      <fluid_density>1030</fluid_density>
    </plugin>

    <plugin name="fish_tail" filename="libLiftDragPlugin.so">
      <link_name>tail_link</link_name>
      <air_density>1000</air_density>
      <cla>0.2969</cla>
      <cla_stall>-0.1044</cla_stall>
      <cda>0</cda>
      <cda_stall>0.1044</cda_stall>
      <alpha_stall>0.3368</alpha_stall>
      <a0>0</a0>
      <area>0.041820095</area>
      <upward>-0.330514 0.943801 0</upward>
      <forward>0.943801  0.330514 0</forward>
      <cp>0.14137 0.12445 0.02142</cp>
    </plugin>

  </gazebo>

  <!-- FOR ROS CONTROL -->
  <transmission name="tran1">
    <type>transmission_interface/SimpleTransmission</type>
    <joint name="tail_joint">
      <hardwareInterface>EffortJointInterface</hardwareInterface>
    </joint>
    <actuator name="motor1">
      <hardwareInterface>EffortJointInterface</hardwareInterface>
      <mechanicalReduction>1</mechanicalReduction>
    </actuator>
  </transmission>

</robot>

